/root/miniforge3/lib/python3.10/site-packages/tensorflow_io/python/ops/__init__.py:98: UserWarning: unable to load libtensorflow_io_plugins.so: unable to open file: libtensorflow_io_plugins.so, from paths: ['/root/miniforge3/lib/python3.10/site-packages/tensorflow_io/python/ops/libtensorflow_io_plugins.so']
caused by: ["[Errno 2] The file to load file system plugin from does not exist.: '/root/miniforge3/lib/python3.10/site-packages/tensorflow_io/python/ops/libtensorflow_io_plugins.so'"]
  warnings.warn(f"unable to load libtensorflow_io_plugins.so: {e}")
/root/miniforge3/lib/python3.10/site-packages/tensorflow_io/python/ops/__init__.py:104: UserWarning: file system plugins are not loaded: unable to open file: libtensorflow_io.so, from paths: ['/root/miniforge3/lib/python3.10/site-packages/tensorflow_io/python/ops/libtensorflow_io.so']
caused by: ['/root/miniforge3/lib/python3.10/site-packages/tensorflow_io/python/ops/libtensorflow_io.so: cannot open shared object file: No such file or directory']
  warnings.warn(f"file system plugins are not loaded: {e}")
Traceback (most recent call last):
  File "/UltimeTradingBot/Binance-Fast-Trade-Bot/modules/abj_ai_buy_signal_vBinance.py", line 332, in <module>
    MetaData=pd.read_csv("../Data/MetaData.csv")
  File "/root/miniforge3/lib/python3.10/site-packages/pandas/util/_decorators.py", line 211, in wrapper
    return func(*args, **kwargs)
  File "/root/miniforge3/lib/python3.10/site-packages/pandas/util/_decorators.py", line 331, in wrapper
    return func(*args, **kwargs)
  File "/root/miniforge3/lib/python3.10/site-packages/pandas/io/parsers/readers.py", line 950, in read_csv
    return _read(filepath_or_buffer, kwds)
  File "/root/miniforge3/lib/python3.10/site-packages/pandas/io/parsers/readers.py", line 605, in _read
    parser = TextFileReader(filepath_or_buffer, **kwds)
  File "/root/miniforge3/lib/python3.10/site-packages/pandas/io/parsers/readers.py", line 1442, in __init__
    self._engine = self._make_engine(f, self.engine)
  File "/root/miniforge3/lib/python3.10/site-packages/pandas/io/parsers/readers.py", line 1735, in _make_engine
    self.handles = get_handle(
  File "/root/miniforge3/lib/python3.10/site-packages/pandas/io/common.py", line 856, in get_handle
    handle = open(
FileNotFoundError: [Errno 2] No such file or directory: '../Data/MetaData.csv'

During handling of the above exception, another exception occurred:

Traceback (most recent call last):
  File "<string>", line 1, in <module>
  File "/UltimeTradingBot/Binance-Fast-Trade-Bot/modules/abj_ai_buy_signal_vBinance.py", line 334, in <module>
    MetaData=get_crypto_metadata(pairs)
  File "/UltimeTradingBot/Binance-Fast-Trade-Bot/modules/abj_ai_buy_signal_vBinance.py", line 311, in get_crypto_metadata
    symbol_launch_week_stamp   = give_first_kline_open_stamp('1w', this_id, 1499990400000 )
  File "/UltimeTradingBot/Binance-Fast-Trade-Bot/modules/abj_ai_buy_signal_vBinance.py", line 288, in give_first_kline_open_stamp
    kline_data = urllib.request.urlopen(url_to_get).read().decode("utf-8")
  File "/root/miniforge3/lib/python3.10/urllib/request.py", line 216, in urlopen
    return opener.open(url, data, timeout)
  File "/root/miniforge3/lib/python3.10/urllib/request.py", line 525, in open
    response = meth(req, response)
  File "/root/miniforge3/lib/python3.10/urllib/request.py", line 634, in http_response
    response = self.parent.error(
  File "/root/miniforge3/lib/python3.10/urllib/request.py", line 557, in error
    result = self._call_chain(*args)
  File "/root/miniforge3/lib/python3.10/urllib/request.py", line 496, in _call_chain
    result = func(*args)
  File "/root/miniforge3/lib/python3.10/urllib/request.py", line 749, in http_error_302
    return self.parent.open(new, timeout=req.timeout)
  File "/root/miniforge3/lib/python3.10/urllib/request.py", line 525, in open
    response = meth(req, response)
  File "/root/miniforge3/lib/python3.10/urllib/request.py", line 634, in http_response
    response = self.parent.error(
  File "/root/miniforge3/lib/python3.10/urllib/request.py", line 563, in error
    return self._call_chain(*args)
  File "/root/miniforge3/lib/python3.10/urllib/request.py", line 496, in _call_chain
    result = func(*args)
  File "/root/miniforge3/lib/python3.10/urllib/request.py", line 643, in http_error_default
    raise HTTPError(req.full_url, code, msg, hdrs, fp)
urllib.error.HTTPError: HTTP Error 400: Bad Request
Unclosed client session
client_session: <aiohttp.client.ClientSession object at 0xffff676685e0>
