/root/miniforge3/lib/python3.10/site-packages/tensorflow_io/python/ops/__init__.py:98: UserWarning: unable to load libtensorflow_io_plugins.so: unable to open file: libtensorflow_io_plugins.so, from paths: ['/root/miniforge3/lib/python3.10/site-packages/tensorflow_io/python/ops/libtensorflow_io_plugins.so']
caused by: ["[Errno 2] The file to load file system plugin from does not exist.: '/root/miniforge3/lib/python3.10/site-packages/tensorflow_io/python/ops/libtensorflow_io_plugins.so'"]
  warnings.warn(f"unable to load libtensorflow_io_plugins.so: {e}")
/root/miniforge3/lib/python3.10/site-packages/tensorflow_io/python/ops/__init__.py:104: UserWarning: file system plugins are not loaded: unable to open file: libtensorflow_io.so, from paths: ['/root/miniforge3/lib/python3.10/site-packages/tensorflow_io/python/ops/libtensorflow_io.so']
caused by: ['/root/miniforge3/lib/python3.10/site-packages/tensorflow_io/python/ops/libtensorflow_io.so: cannot open shared object file: No such file or directory']
  warnings.warn(f"file system plugins are not loaded: {e}")
